Workbook
Name 开放范围: [1]Sheet2!$L$27:$L$30

Sheet 填表说明
D4: 为进一步落实总部数字化部关于“中台标准化及开放性提升”工作要求，经过前期研讨，对服务、接口、参数等属性进行扩充，请各中台于5月15日完成相关信息收集并反馈。 1.微服务sheet需补充完善D、G、J、L、M、N、O、P、Q、R、S列； 2.服务sheet页需补充完善I、L、M列； 3.接口sheet页需补充完善E、F、I、K、L、M、Q、R、S、T列； 4.出入参信息sheet页需补充，或按照《业务中台接口出入参收集--模板（word）》进行反馈。
D19: 关于出入参信息sheet页，参数信息表转化为标准模板的示例说明
D20: 请求参数字段表 | J20: Json示例： | K20: [{"default":"查询条件","name":"filters","length":"","reqType":"3","type":"object","required":true,"desc":"查询条件","child":[{"default":"设备型号","name":"model","length":"42","reqType":"3","type":"string","required":false,"desc":"设备型号","child":[]}, {"default":"检测试验项目ID","name":"testItemId","length":"","reqType":"3","type":"string","required":false,"desc":"检测试验项目ID","child":[]}, {"default":"检测试验项目编码","name":"testItemCode","length":"","reqType":"3","type":"string","required":true,"desc":"检测试验项目编码","child":[]}, {"default":"源端系统中设备类型编码","name":"sourceEquipTypeCode","length":"42","reqType":"3","type":"string","required":true,"desc":"源端系统中设备类型编码","child":[]}, {"default":"设备类型编码标识","name":"equipTpyeFlag","length":"2","reqType":"3","type":"int","required":false,"desc":"设备类型编码标识","child":[]}, {"default":"部门标识","name":"department","length":"42","reqType":"3","type":"string","required":false,"desc":"部门标识","child":[]}, {"default":"检测试验专业编码","name":"testMajorCode","length":"","reqType":"3","type":"array","required":false,"desc":"检测试验专业编码","child":[]}, {"default":"检测试验性质编码","name":"testNatureCode","length":"","reqType":"3","type":"array","required":false,"desc":"检测试验性质编码","child":[]}, {"default":"标签编码列表","name":"tagCodeList","length":"","reqType":"3","type":"array","required":false,"desc":"标签编码列表","child":[]}, {"default":"是否查询逻辑删除数据","name":"allFlag","length":"2","reqType":"3","type":"int","required":false,"desc":"是否查询逻辑删除数据","child":[]}]}, {"default":"页数","name":"page","length":"10","reqType":"3","type":"int","required":false,"desc":"页数",,"child":[]}, {"default":"每页中条数","name":"perPage","length":"10","reqType":"3","type":"int","required":false,"desc":"每页中条数","child":[]}]
D21: 字段名称 | E21: 字段含义 | F21: 字段说明 | J21: 蓝色部分为"对象filter"的嵌套体
D22: default | E22: 默认值 | F22: 预留字段
D23: name | E23: 参数英文名称 | F23: 例：orgId。
D24: length | E24: 参数长度 | F24: 例：1000。
D25: reqType | E25: 请求参数类型 | F25: 包含4种请求参数类型，0-path；1-params；2-header；3-body。
D26: type | E26: 类型 | F26: 包含7中类型，Object-对象类型；list-数组类型；String-字符类型；Boolean-布尔类型；Float-单精度浮点型；Double-双精度浮点型；Int-整型；嵌套体一般常用Object或者Array。不建议额外新增类型。
D27: required | E27: 是否必填 | F27: 包含2种类型，false-非必填；true-必填。
D28: desc | E28: 参数说明 | F28: 对参数信息的业务描述。
D29: child | E29: 嵌套体 | F29: 如果该参数为Object或者Array，嵌套参数需要按照Json模板，嵌套在嵌套体中。
J33: 注意事项： | K33: 入参/出参语句中，主Json串的起始符为"[",结束符为"]"，中间用","分隔。
K34: 嵌套时，只需要将嵌套体插入到对应参数的child["嵌套体"]字段中。
K35: 嵌套结束时，不需要用","分隔。
D37: 请求Json模板： | E37: [{"default":"","name":"","length":"","reqType":"1","type":"","required":"","desc":"无","child":[]}]
D42: 返回参数字段表 | J42: Json示例： | K42: [{"default":"","name":"code","length":"10","type":"string","desc":"状态码","child":[]}, {"default":"","name":"message","length":"200","type":"string","desc":"错误信息","child":[]}, {"default":"","name":"data","length":"","type":"object","desc":"结果数据","child":[{"default":"","name":"current","length":"","type":"int","desc":"页号","order":"0","child":[]}, {"default":"","name":"size","length":"","type":"int","desc":"页大小","child":[]}, {"default":"","name":"pages","length":"","type":"int","desc":"总页数","child":[]}, {"default":"","name":"total","length":"","type":"int","desc":"总记录数","child":[]}, {"default":"","name":"records","length":"","type":"array","desc":"分页数据对象","child":[]}]}]
D43: 字段名称 | E43: 字段含义 | F43: 字段说明 | J43: 蓝色部分为对象"data"的嵌套体
D44: default | E44: 默认值 | F44: 预留字段
D45: name | E45: 参数英文名称 | F45: 例：orgId。
D46: length | E46: 参数长度 | F46: 例：1000。
D47: type | E47: 类型 | F47: 包含7中类型，Object-对象类型；list-数组类型；String-字符类型；Boolean-布尔类型；Float-单精度浮点型；Double-双精度浮点型；Int-整型；嵌套体一般常用Object或者Array。不建议额外新增类型。
D48: desc | E48: 参数说明 | F48: 对参数信息的业务描述。
D49: child | E49: 嵌套体 | F49: 如果该参数为Object或者Array，嵌套参数需要按照Json模板，嵌套在嵌套体中。
J53: 注意事项： | K53: 入参/出参语句中，主Json串的起始符为"[",结束符为"]"，中间用","分隔。
K54: 嵌套时，只需要将嵌套体插入到对应参数的child["嵌套体"]字段中。
K55: 嵌套结束时，不需要用","分隔。
D59: 返回Json模板： | E59: [{"default":"","name":"","length":"",,"type":"",,"desc":"无","child":[]}]

Sheet 项目中台微服务
A1: 特别说明：下表表头带*号的列为必填项，其余为选填项
A2: 序号 | B2: *微服务中文名 | C2: *微服务英文名 | D2: 微服务版本 | E2: *微服务描述 | F2: *主管业务部门 | G2: *建设类型 | H2: *路由类型 | I2: 后端微服务名 | J2: 后端服务器URI | K2: 前端访问路径 | L2: 后端转发路径 | M2: *超时时间 | N2: 失败重试 | O2: 重试间隔 | P2: 前端区分参数 | Q2: 请求头参数 | R2: 优先级 | S2: *去除前缀优先级
A3: 说明 | B3: 微服务中文名，格式应为：xx业务中台-微服务功能中文名 | C3: 微服务英文名，一般与"I列"后端微服务名一致，或可以与后端微服务名一一对应 | D3: 微服务当前版本 | E3: 微服务对应业务能力描述 | F3: 微服务所属管理部门 | G3: 统推/自建 | H3: 服务发现/反向代理 | I3: 本中台注册中心上微服务英文名，路由类型为服务发现时该字段必填*，反向代理无需填写 | J3: 路由类型为反向代理时该字段必填*，服务发现无需填写 | K3: 1、前端访问路径是指调用方访问路径，与后端转发路径是映射关系。 匹配规则：/前端访问路径 转发/后端微服务名/后端转发路径2、该字段在管理后台进行逐一录入时为必填字段，匹配的默认值为/微服务英文名/，批量导入模板中设置为非必填字段。如果不填写将给默认值/微服务英文名/，否则将按照填写路径进行导入。 3、如前端访问路径有多个需以英文逗号分隔。 4、必须以/开头 | L3: 1、路由转发目标路径，支持精确匹配前端访问路径的变量。 匹配规则：/前端访问路径 转发/后端微服务名/后端转发路径 2、该字段在管理后台进行逐一录入时为必填字段，匹配的默认值为/{$1}，批量导入模板中设置为非必填字段。如果不填写将给默认值/{$1}，否则将按照填写路径进行导入。 3、必须以/开头 | M3: 超时时间单位:ms(毫秒) | N3: 单位次 | O3: 单位毫秒 | P3: 1.该参数作为路由断言的匹配条件之一，以确保只有满足特定条件的请求才会被路由到特定的处理程序或服务。用以提高网络的可靠性、性能和灵活性。 2.{前端区分参数}是用以进一步细化路由决策的机制，表示真实路径query中的部分参数映射关系，用于在前端访问路径和接口地址相同时，使用不同入参键值来辅助路由匹配至不同后端微服务。 | Q3: 1.该参数作为路由断言的匹配条件之一，以确保只有满足特定条件的请求才会被路由到特定的处理程序或服务。用以提高网络的可靠性、性能和灵活性。 2.{请求头参数}是用以进一步细化路由决策的机制，表示请求头header中的部分参数映射关系，用于在前端访问路径和接口地址相同时，使用不同入参键值来辅助路由匹配至不同后端微服务名 | R3: 1.该参数作1.该参数作为路由断言的匹配条件之一，以确保只有满足特定条件的请求才会被路由到特定的处理程序或服务。用以提高网络的可靠性、性能和灵活性。 2.{优先级}是用于进一步细化路由决策的机制。在多个断言都适用的情况下，优先级高的断言会优先决定请求的路由。 字段要求： 1.路由断言匹配时优先级生效，微服务英文名匹配时不生效。 2.数值越小，优先级越高。 | S3: 用以生成实际路由地址，是从前端访问路径最左端开始去除的路径层级数量。 字段要求： 1.个数不可大于前端访问路径最小可以去除的个数。 2.前端页面去除前缀个数默认为1,批量导入需要填写具体去除个数。
A4: 示例 | B4: 项目管理业务中台-项目研判中心-总控规模测算服务 | C4: buaa-sj-overallcontroller | D4: v1.0.1 | E4: 支撑综合计划总控规模测算业务，提供电网基建专项、零星购置专项、生产技改专项、生产大修专项、电网小型基建专项等16个专项投资需求预测结果查询的能力，实现专项规模测算结果查询的目标。 | F4: 发展部 | G4: 统推 | H4: 服务发现 | I4: buaa-sj-overallcontroller | J4: http://ip:port或http://domain:port 当模板配置为ip:port时后台会默认在前缀加上http:// | K4: /buaa-sj-overallcontroller/** | L4: /{$1} 结合前端访问路径及后端转发路径的填写内容，路由结果为： /pmp-sj-overallcontroller/**转发至http://pmp-sj-overallcontroller/{$1} | M4: 10000(10秒) | N4: 1（1次） | O4: 1000（1秒） | P4: professionalKind=0101 | Q4: professionalHeaderKing=01 | R4: 3 | S4: 例1：前端访问路径：/a/b/c/** 去除前缀个数：0 最终匹配路径为：/a/b/c/** 例2：前端访问路径：/a/b/c/** 去除前缀个数：1 最终匹配路径为：/b/c/** 以此类推
A5: 1 | B5: 项目管理业务中台-项目研判中心-总控规模测算服务 | C5: buaa-sj-overallcontroller | D5: v1.0.1 | E5: 支撑综合计划总控规模测算业务，提供电网基建专项、零星购置专项、生产技改专项、生产大修专项、电网小型基建专项等16个专项投资需求预测结果查询的能力，实现专项规模测算结果查询的目标。 | F5: 发展部 | G5: 统推 | H5: 服务发现 | I5: buaa-sj-overallcontroller | K5: /buaa-sj-overallcontroller/** | M5: 10000 | S5: 1
A6: 2 | B6: 项目管理业务中台-项目研判中心-发展战略分析服务 | C6: buaa-sj-investment | D6: v1.0.1 | E6: 支撑宏观形势分析业务，提供公司发展战略信息维护、分析及政策功能化分类能力，实现公司发展战略分析与政策功能化分类的目标。 | F6: 发展部 | G6: 统推 | H6: 服务发现 | I6: buaa-sj-investment | K6: /buaa-sj-investment/** | M6: 10000 | S6: 1
A7: 3 | B7: 项目管理业务中台-项目研判中心-新能源云分析服务 | C7: buaa-sj-newenergy-analysis | D7: v1.0.1 | E7: 新能源接入测算类服务 | F7: 发展部 | G7: 统推 | H7: 服务发现 | I7: buaa-sj-newenergy-analysis | K7: /buaa-sj-investment/** | M7: 10000 | S7: 1
A8: 4 | B8: 项目管理业务中台-项目研判中心-政策分析服务 | C8: buaa-sj-policy-analysis | D8: v1.0.1 | E8: 重大政策维护类服务 | F8: 发展部 | G8: 统推 | H8: 服务发现 | I8: buaa-sj-policy-analysis | K8: /buaa-sj-investment/** | M8: 10000 | S8: 1
A9: 5 | B9: 项目管理业务中台-项目研判中心-投资研判服务 | C9: buaa-sj-investment-judgment | D9: v1.0.1 | E9: 投资策略研判类服务 | F9: 发展部 | G9: 统推 | H9: 服务发现 | I9: buaa-sj-investment-judgment | K9: /buaa-sj-investment/** | M9: 10000 | S9: 1
A10: 6 | B10: 项目管理业务中台-项目储备中心-项目立项管理服务 | C10: buaa-st-project | D10: v1.0.1 | E10: 项目前期相关服务，提供储备重点任务维护、项目需求管理、项目可研维护等服务，支撑项目需求统筹、项目可研评审等业务。 | F10: 发展部 | G10: 统推 | H10: 服务发现 | I10: buaa-st-project | K10: /buaa-st-center/** | M10: 10000 | S10: 1
A11: 7 | B11: 项目管理业务中台-项目储备中心-储备监督检查服务 | C11: buaa-st-check | D11: v1.0.1 | E11: 储备项目监督检查相关服务，提供项目关联分析、储备监督检查等能力，支撑项目储备质量提升。 | F11: 发展部 | G11: 统推 | H11: 服务发现 | I11: buaa-st-check | K11: /buaa-st-center/** | M11: 10000 | S11: 1
A12: 8 | B12: 项目管理业务中台-项目储备中心-储备项目管理服务 | C12: buaa-st-reserve | D12: v1.0.1 | E12: 储备项目管理相关服务，提供储备项目维护、查询、入库、出库等服务，支撑项目常态储备。 | F12: 发展部 | G12: 统推 | H12: 服务发现 | I12: buaa-st-reserve | K12: /buaa-st-center/** | M12: 10000 | S12: 1
A13: 9 | B13: 项目管理业务中台-项目储备中心-储备项目查询服务 | C13: buaa-st-query | D13: v1.0.1 | E13: 储备项目其他相关服务，提供来源追溯、文件管理、项目排序等服务，辅助项目储备管理 | F13: 发展部 | G13: 统推 | H13: 服务发现 | I13: buaa-st-query | K13: /buaa-st-center/** | M13: 10000 | S13: 1
A14: 10 | B14: 项目管理业务中台-项目储备中心-储备项目分析服务 | C14: buaa-st-analysis | D14: v1.0.1 | E14: 项目分析统计相关服务，提供储备项目进度、结构、质量分析等服务，支撑项目储备进度跟踪等。 | F14: 发展部 | G14: 统推 | H14: 服务发现 | I14: buaa-st-analysis | K14: /buaa-st-center/** | M14: 10000 | S14: 1
A15: 11 | B15: 项目管理业务中台-项目储备中心-储备微应用后端服务 | C15: buaa-st-micro-app | D15: v1.0.1 | E15: 山西微应用服务（试点应用服务），单独部署，与中心服务解耦。 | F15: 发展部 | G15: 统推 | H15: 服务发现 | I15: buaa-st-micro-app | K15: /buaa-st-center/** | M15: 10000 | S15: 1
A16: 12 | B16: 项目管理业务中台-项目合规中心-项目合规处置服务 | C16: buaa-pac-robot | D16: v1.0.1 | E16: 支撑各专项项目合规检测业务，提供储备项目入库合规检测等功能，检查内容包括项目关键字段、项目编码、计划信息、专业要求、专业管理界面、专项批复界面。 | F16: 发展部 | G16: 统推 | H16: 服务发现 | I16: buaa-pac-robot | K16: /buaa-pac-robot/** | M16: 10000 | S16: 1
... A68: 64 | B68: 项目管理业务中台-项目计划中心-分解管理服务 | C68: buaa-plan-decompose | D68: v1.0.1 | E68: 根据业务阶段拆分，同属于计划分解业务的服务 | F68: 发展部 | G68: 统推 | H68: 服务发现 | I68: buaa-plan-decompose | K68: /buaa-plan-center/** | M68: 10000 | S68: 1

Sheet 项目中台服务
A1: 特别说明：下表表头带*号的列为必填项，其余为选填项
A2: 序号 | B2: *所属中台 | C2: *所属中心 | D2: *服务中文名 | E2: *服务英文名 | F2: 服务编码（ID/唯一标识） | G2: *服务简介 | H2: 服务更新时间 | I2: 支撑应用
A3: 说明 | B3: 所属中台中文名 | C3: 所属中心中文名 | D3: 服务中文名 | E3: 服务英文名 | F3: 如果存在编码，编码格式例旧，如果尚未生成编码，编码格式为：业务中台首字母缩写_中心缩写_六位序号 | G3: 服务简介 | H3: 服务最后一次进行内容或功能更新的时间，当前可不填，后续线上化管理自动获取 | I3: 调用该服务的应用名称，当前可不填，后续线上化管理自动获取
A4: 示例 | B4: 客户服务业务中台 | C4: 工单中心 | D4: 计量换表查询服务 | E4: osg-woc0016 | F4: buaa_sj_zxtzcsjgcx | G4: 提供接收来自营销的待换表计划、换表后待签字信息等服务 | H4: 45351 | I4: PMS3.0/营销2.0
A5: 1 | B5: 项目管理业务中台 | C5: 项目资源中心 | D5: 项目组织机构发布 | E5: buaa-res-projectOrganizationRelease | F5: buaa_res_bbfbService | G5: 项目组织机构发布服务主要适用于支撑项目组织机构管理、变更查询相关业务，提供组织机构发布服务，支撑各系统及时获取组织机构更新信息，保证省侧和总部编码规则一致。
A6: 2 | B6: 项目管理业务中台 | C6: 项目资源中心 | D6: 项目编码校核 | E6: buaa-res-codeVerification | F6: buaa_res_bmjhService | G6: 项目编码校核服务主要适用于支撑各专项进行项目编码校核业务，提供项目编码校核服务，支撑项目编码生成之后，由于项目编码的项目分类、项目所属单位、申请年份等基本信息发生变化，重新调用项目编码生成服务生成新的项目编码，保证项目编码与基本信息的一致性。
A7: 3 | B7: 项目管理业务中台 | C7: 项目资源中心 | D7: 项目编码服务 | E7: buaa-res-projectCodeGeneration | F7: buaa_res_bmscService | G7: 项目编码服务主要适用于支撑各专项项目编码生成业务，提供编码采用“基础码+扩展码”组合生成服务，支撑依据专项类型、项目分类、工程顺序码、管理类型、项目出资单位等信息生成项目编码。
A8: 4 | B8: 项目管理业务中台 | C8: 项目资源中心 | D8: 项目编码溯源 | E8: buaa-res-ProjectCodeTraceability | F8: buaa_res_bmsyService | G8: 项目编码溯源服务主要适用于支撑各业务进行项目编码溯源业务，提供项目编码溯源服务，支撑项目编码生成之后，由于组合生成项目编码的项目分类、项目所属单位、申请年份等基本信息发生变化，需要重新调用项目编码生成服务，生成新的项目编码。
A9: 5 | B9: 项目管理业务中台 | C9: 项目资源中心 | D9: 项目手动贴签 | E9: buaa-res-bqHandleService | F9: buaa_res_bqHandleService | G9: 项目手动贴签服务主要适用于支撑各业务进行自定义标签及手动贴签业务，提供手动贴签服务，支撑业务根据业务需求自定义标签及手动贴签。
A10: 6 | B10: 项目管理业务中台 | C10: 项目资源中心 | D10: 项目标签管理 | E10: buaa-res-itemLabelManage | F10: buaa_res_bqManageService | G10: 项目标签管理服务主要适用于支撑XX业务，提供项目标签管理服务，支撑业务对标签分类、主题、标签进行管理。
A11: 7 | B11: 项目管理业务中台 | C11: 项目资源中心 | D11: 项目标签检索 | E11: buaa-res-itemLabelSearchService | F11: buaa_res_bqSearchService | G11: 项目标签检索服务主要适用于支撑按照标签查询项目相关业务，提供项目标签检索服务，支撑业务按照标签的维度对项目进行查询。
A12: 8 | B12: 项目管理业务中台 | C12: 项目资源中心 | D12: 抽数服务 | E12: buaa-res-isolateService | F12: buaa_res_cqsjService | G12: 抽数服务主要适用于支撑从数据中台抽取数据业务，提供抽数服务，支撑各业务从数据中台进行数据抽取。
A13: 9 | B13: 项目管理业务中台 | C13: 项目资源中心 | D13: 项目分类管理 | E13: buaa-res-classification management-Service | F13: buaa_res_flglService | G13: 项目分类管理服务主要适用于支撑各专项进行项目分类管理业务，提供项目编码的分类服务，通过配置专业系统与项目分类关系，预防专业系统生成错误的项目编码。
A14: 10 | B14: 项目管理业务中台 | C14: 项目资源中心 | D14: I6000服务 | E14: buaa-res-i6000service | F14: buaa_res_i6000service | G14: I6000服务主要适用于支撑I6000获取项目系统指标业务，提供I600服务，支撑I6000系统统计中台服务的指标信息。
A15: 11 | B15: 项目管理业务中台 | C15: 项目资源中心 | D15: 项目信息初始维护服务 | E15: buaa-res-imotpService | F15: buaa_res_imotpService | G15: 项目信息初始维护服务适用于16个专项项目初始信息的维护，提供项目信息初始维护服务，支撑项目、子项目、项目包等的新增、修改、删除、查询等，完成与规划、储备的衔接，实现规范项目的源头管理。
A16: 12 | B16: 项目管理业务中台 | C16: 项目资源中心 | D16: 项目非结构化文档解析 | E16: buaa-res-unstructured DocumentParsing | F16: buaa_res_jgjxService | G16: 项目非结构化文档解析服务主要适用于支撑项目非结构化解析业务，提供项目信息结构化解析服务，实现对项目内容和项目可研报告、项目需求报告等非结构文档内容的提取，智能填充到必要性、可行性、经济性、规范性等结构化字段，减少业务人员的操作量，提供信息录入效率。
... A153: 149 | B153: 项目管理业务中台 | C153: 项目执行中心 | D153: 项目建项情况分析 | E153: buaa-exec-anaComQuery | F153: buaa_exec_anaComQuery | G153: 按照各专业部门计划项目执行检查业务要求，需要完善项目建项率分析服务，增加为各专项提供计划项目ERP建项数量、规模、建项率信息的功能，支撑各单位各专项跟踪监控项目建项进度，保障建项业务及时开展。
A154: 150 | B154: 项目管理业务中台 | C154: 项目执行中心 | D154: 建项信息维护 | E154: buaa-exec-autoProCreat | F154: buaa_exec_autoProCreat | G154: 提供项目自动建项服务，支撑总分部、直属单位、省（市）公司的各专业部门查询符合建项条件的待建项目清单，自动建项服务将项目建项指令信息发送给ERP,实现项目自动建项。 | J154: 此服务已拆分为ERP中台化 改造应用，不在提供中心服务，未注册调度组件
A155: 151 | B155: 项目管理业务中台 | C155: 项目执行中心 | D155: 单项工程施工图预算管理 | E155: buaa-exec-budgetProjectUpdate | F155: buaa_exec_budgetProjectUpdate | G155: 实现单项工程建筑、安装、设备、其它费用、基本预备费、特殊项目费、工程静态投资、价差预备费、建设期贷款利息、工程动态投资等施工图预算信息维护，支撑全网单项工程施工图预算同源。 提供单项工程级别单项工程建筑、安装、设备、其它费用、基本预备费、特殊项目费、工程静态投资、价差预备费、建设期贷款利息、工程动态投资等施工图预算信息，支撑各专业系统作为招标控制的依据和五算对比分析。
A156: 152 | B156: 项目管理业务中台 | C156: 项目执行中心 | D156: 项目关闭情况分析 | E156: buaa-exec-closureSituation | F156: buaa_exec_closureSituation | G156: 基于数据中台，提供项目验收阶段项目关闭的项目数量、金额情况查询服务，支持各单位、各专项的整体占比分析。
A157: 153 | B157: 项目管理业务中台 | C157: 项目执行中心 | D157: 项目竣工验收分析 | E157: buaa-exec-comAccAnalysis | F157: buaa_exec_comAccAnalysis | G157: 基于数据中台，提供项目验收阶段关键指标分析服务，包括完工项目数、工程决算项目数、费用结算项目数、资产转资项目数、项目关闭项目数，提供项目完工验收、项目关闭、财务入账、结算转资业务完成情况查询。
A158: 154 | B158: 项目管理业务中台 | C158: 项目执行中心 | D158: 项目投产情况分析 | E158: buaa-exec-commissioningAnalysis | F158: buaa_exec_commissioningAnalysis | G158: 支撑各单位查询电网基建项目即将投产预警项目信息、投产不实项目信息、实现已投产但当年入账金额与当年预算金额的比率小于一定比例项目清单信息、项目完工率、项目完工规模、年度计划金额和项目完工率等信息，并提供专项完工率排名、单位完工率排名情况
A159: 155 | B159: 项目管理业务中台 | C159: 项目执行中心 | D159: 项目合同履约信息查询 | E159: buaa-exec-conPerQuery | F159: buaa_exec_conPerQuery | G159: 提供项目相关合同的部分履约信息查询服务，主要包含供应商名称、合同名称、合同交货期、确认交货日期、验收日期、投运日期等信息。
A160: 156 | B160: 项目管理业务中台 | C160: 项目执行中心 | D160: 项目合同签订情况分析 | E160: buaa-exec-contractAnalysis | F160: buaa_exec_contractAnalysis | G160: 支撑各单位查询项目合同签订率、签订规模、年度计划金额等信息，并提供专项合同签订率排名、单位合同签订率排名情况。
A161: 157 | B161: 项目管理业务中台 | C161: 项目执行中心 | D161: 项目合同明细信息查询 | E161: buaa-exec-contractDetailsQuery | F161: buaa_exec_contractDetailsQuery | G161: 提供项目相关的所有合同明细信息查询服务，主要包含合同生效日期、含税金额、供应商名称、卖方合同编号、买方联系人、买方电话、卖方联系人、卖方联系电话、质保期等信息。
A162: 158 | B162: 项目管理业务中台 | C162: 项目执行中心 | D162: 项目合同付款情况查询 | E162: buaa-exec-contractPaymentQuery | F162: buaa_exec_contractPaymentQuery | G162: 基于数据中台，提供各专项项目合同付款情况查询服务。
A163: 159 | B163: 项目管理业务中台 | C163: 项目执行中心 | D163: 项目关键管控节点动态校核 | E163: buaa-exec-controlNodesDynamic | F163: buaa_exec_controlNodesDynamic | G163: 提供项目关键节点的执行情况查询服务，实现关键计划节点进度信息展示。
A164: 160 | B164: 项目管理业务中台 | C164: 项目执行中心 | D164: 项目成本入账情况分析 | E164: buaa-exec-costIncidenceAnalysis | F164: buaa_exec_costIncidenceAnalysis | G164: 基于数据中台，提供项目成本发生率分析服务：支持合同进度确认百分比、本年财务入账百分比、累计财务入账百分比、合同入账占比等项目实施阶段关键指标分析服务。 | J164: 此服务中接口为 webservice接口，无法注册调度组件
A165: 161 | B165: 项目管理业务中台 | C165: 项目执行中心 | D165: 项目成本信息查询 | E165: buaa-exec-costInformationQuery | F165: buaa_exec_costInformationQuery | G165: 基于数据中台，提供项目实际成本查询服务，包括项目信息、WBS元素、单项工程编码、单项工程名称、项目名称、实际成本等信息。
A166: 162 | B166: 项目管理业务中台 | C166: 项目执行中心 | D166: ERP建项结果反馈 | E166: buaa-exec-erpFeedBack | F166: buaa_exec_erpFeedBack | G166: 支撑ERP系统将建项结果进行反馈。
A167: 163 | B167: 项目管理业务中台 | C167: 项目执行中心 | D167: 项目估算、概算、预算、结算、决算对比分析 | E167: buaa-exec-fiveCalcu | F167: buaa_exec_fiveCalcu | G167: 提供项目估算、概算、预算、结算、决算对比分析，应用于各单位对项目估算、概算、预算、结算、决算进行查询，实现估算、概算、预算、结算、决算的查询和对比分析等。
A168: 164 | B168: 项目管理业务中台 | C168: 项目执行中心 | D168: 项目形象进度分析 | E168: buaa-exec-imageProgressAnalysis | F168: buaa_exec_imageProgressAnalysis | G168: 提供工程形象进度权重或财务入账金额权重维护服务，计算项目当前月项目的形象进度百分比、评估值。提供形象进度百分比的录入、修改服务，支持各专项当前年度、月份的形象进度 百分比的维护。
A169: 165 | B169: 项目管理业务中台 | C169: 项目执行中心 | D169: 项目执行情况管理 | E169: buaa-exec-implementationQuery | F169: buaa_exec_implementationQuery | G169: 提供项目执行全过程关键业务数据信息，主要包含ERP项目编码、ERP建项名称、项目建项数量、建项时间、项目建项总投资、年度预算（含税）、物资需求提报（采购申请）时间、物资合同签订（采购订单）时间、物资到货（物资凭证）时间、累计物资需求提报金额、累计成本发生金额等信息查询；各专项WBS结构、基本信息、组织信息查询、维护；实现对项目执行基本信息的新增、修改、查询；实现项目季度填报业务；支撑科技专项归档材料信息同源维护及查询。
A170: 166 | B170: 项目管理业务中台 | C170: 项目执行中心 | D170: 项目初设信息查询 | E170: buaa-exec-initialDesignQuery | F170: buaa_exec_initialDesignQuery | G170: 基于数据中台，提供给电网基建专项查询项目的初设批复日期、初设投资额等信息。
A171: 167 | B171: 项目管理业务中台 | C171: 项目执行中心 | D171: 项目投资完成情况分析 | E171: buaa-exec-invComAna | F171: buaa_exec_invComAna | G171: 基于数据中台，提供项目投资完成情况查询，包括投资预算、执行成本。支持各单位、各专项的同比分析服务。
A172: 168 | B172: 项目管理业务中台 | C172: 项目执行中心 | D172: 项目招标信息查询 | E172: buaa-exec-inviteTendersQuery | F172: buaa_exec_inviteTendersQuery | G172: 提供项目相关的采购招标及中标结果信息查询服务，主要包含项目编码、采购申请中标结果ID、采购申请基本信息ID、采购申请凭证类型ID、省公司ID、采购批次计划ID、需求单位名称、需求单位编码、网省采购申请标识、总部采购申请标识、数量、计量单位、最后一批交货时间、物料编码ID等信息。
A173: 169 | B173: 项目管理业务中台 | C173: 项目执行中心 | D173: 项目决算情况分析 | E173: buaa-exec-itemFinalAccountsAnalysis | F173: buaa_exec_itemFinalAccountsAnalysis | G173: 支撑各单位查询项目决算率、项目决算规模，年度计划金额等信息，并提供专项决算率排名、单位决算率排名情况。
A174: 170 | B174: 项目管理业务中台 | C174: 项目执行中心 | D174: 项目结算情况分析 | E174: buaa-exec-itemSettAnalysis | F174: buaa_exec_itemSettAnalysis | G174: 支撑各单位查询项目结算率、结算规模、年度计划金额等信息，并提供专项结算率排名、单位结算率排名情况。
A175: 171 | B175: 项目管理业务中台 | C175: 项目执行中心 | D175: 项目物资领用情况分析 | E175: buaa-exec-materialsReceiveAnalysis | F175: buaa_exec_materialsReceiveAnalysis | G175: 支撑各单位查询项目物资领用率、领用规模、年度计划金额等信息，并提供专项物资领用率排名、单位物资领用率排名情况;以及物资领用金额占年度预算比例异常项目清单
A176: 172 | B176: 项目管理业务中台 | C176: 项目执行中心 | D176: 里程碑计划查询 | E176: buaa-exec-milestonePlanQuery | F176: buaa_exec_milestonePlanQuery | G176: 里程碑计划提供查询项目里程碑计划信息、项目里程碑计划建设规模信息、单项工程计划建设规模等信息，具体如计划开工时间、计划投产时间、计划开工线路长度、计划开工变电容量等信息。
...

Sheet 项目中台接口
A1: 特别说明：下表表头带*号的列为必填项，其余为选填项
A2: 序号 | B2: *微服务英文名 | C2: *接口中文名 | D2: *接口描述 | E2: *接口版本 | F2: 版本描述 | G2: *接口地址 | H2: *接口请求类型 | I2: *建设类型 | J2: *前端应用访问接口地址 | K2: 超时时间 | L2: 失败重试 | M2: 重试间隔 | N2: *接口类型 | O2: 接口编码 （ID/唯一标识） | P2: *部署位置 | Q2: *数据格式 | R2: *操作类型 | S2: *是否涉及负面清单 | T2: 接口更新时间 | U2: *服务中文名称 | V2: *服务英文名
A3: 1 | B3: buaa-bpp-analyse | C3: 查询公司规划报告信息接口 | D3: 查询专业部门需要维护的公司规划报告信息 | E3: V1.0.1 | G3: /buaa/bpp/planReportMagAction/queryReportInfo | H3: POST | I3: 统推 | J3: /buaa-bpp-analyse/bpp/planReportMagAction/queryReportInfo | N3: restful | O3: buaa_bpp_zxgz_09_cg01 | P3: 内网 | Q3: JSON | R3: 修改 | S3: 否 | T3: 2024-10-24 11:02:23 | U3: 规划成果查询 | V3: buaa-bpp-achievementQuery
A4: 2 | B4: buaa-bpp-analyse | C4: 查询规划评估报告信息接口 | D4: 查询各单位的规划报告上报信息，包括报告名称、报告状态、上报时间、联系人、联系方式等 | E4: V1.0.1 | G4: /admire/bpp/planReportMagAction/queryPlanAssessmentReportInfo | H4: POST | I4: 统推 | J4: /buaa-bpp-analyse/bpp/planReportMagAction/queryPlanAssessmentReportInfo | N4: restful | O4: buaa_bpp_zxgz_09_cg02 | P4: 内网 | Q4: JSON | R4: 修改 | S4: 否 | T4: 2024-10-24 11:02:23 | U4: 规划成果查询 | V4: buaa-bpp-achievementQuery
A5: 3 | B5: buaa-bpp-analyse | C5: 修改公司规划报告上报状态接口 | D5: 上级发展部门对下级单位已上报公司规划报告审核确认，对存在异议的报告退回；下级单位对发展确认的报告上报于上级单位。 | E5: V1.0.1 | G5: /nlsde/bpp/planReportMagAction/updateReportSolidifyState | H5: POST | I5: 统推 | J5: /buaa-bpp-analyse/bpp/planReportMagAction/updateReportSolidifyState | N5: restful | O5: buaa_bpp_zxgz_09_cg03 | P5: 内网 | Q5: JSON | R5: 修改 | S5: 否 | T5: 2024-10-24 11:02:23 | U5: 规划成果查询 | V5: buaa-bpp-achievementQuery
A6: 4 | B6: buaa-bpp-analyse | C6: 规划成果统计查询接口 | D6: 根据规划期间、规划年度、所属单位、成果类型等信息，统计规划成果数量。 | E6: V1.0.1 | G6: /buaa/planCenter/PlanAchiStatistics | H6: POST | I6: 统推 | J6: /buaa-bpp-analyse/planCenter/PlanAchiStatistics | N6: restful | O6: buaa_bpp_zxgz_09_cg04 | P6: 内网 | Q6: JSON | R6: 查询 | S6: 否 | T6: 2024-10-24 11:02:23 | U6: 规划成果查询 | V6: buaa-bpp-achievementQuery
A7: 5 | B7: buaa-bpp-prj | C7: 查询规划投资按地域分解信息接口 | D7: 根据选择的条件，查询规划投资按地域分解信息。 | E7: V1.0.1 | G7: /admire/bpp/planExecutionMagAction/queryInvestDecomposeData | H7: POST | I7: 统推 | J7: /buaa-bpp-analyse/planCenter/110kVUpTransSchedule | N7: restful | O7: buaa_bpp_xmxt_01_xt01 | P7: 内网 | Q7: JSON | R7: 修改 | S7: 否 | T7: 2024-10-24 11:02:23 | U7: 规划全量分析 | V7: buaa-bpp-allAnaly
A8: 6 | B8: buaa-bpp-prj | C8: 修改规划投资按地域分解信息接口 | D8: 根据单位、规划版本、规划滚动年份，修改规划投资按地域分解投资信息。 | E8: V1.0.1 | G8: /nlsde/bpp/planExecutionMagAction/updateInvestDecomposeData | H8: POST | I8: 统推 | J8: /buaa-bpp-analyse/planCenter/35kVDownTransInvest | N8: restful | O8: buaa_bpp_xmxt_01_xt02 | P8: 内网 | Q8: JSON | R8: 修改 | S8: 否 | T8: 2024-10-24 11:02:23 | U8: 规划全量分析 | V8: buaa-bpp-allAnaly
A9: 7 | B9: buaa-bpp-prj | C9: 新增规划投入按地域分解信息 | D9: 新增各单位规划投入按地域分解信息 | E9: V1.0.1 | G9: /buaa/bpp/planExecutionMagAction/addInvestDecomposeData | H9: POST | I9: 统推 | J9: /buaa-bpp-analyse/planCenter/JgPlanningGual | N9: restful | O9: buaa_bpp_xmxt_01_xt03 | P9: 内网 | Q9: JSON | R9: 修改 | S9: 否 | T9: 2024-10-24 11:02:23 | U9: 规划全量分析 | V9: buaa-bpp-allAnaly
A10: 8 | B10: buaa-bpp-analyse | C10: 查询约束指标报表数据接口 | D10: 查看和导出选择单位指定年份的各指标的具体数据 | E10: V1.0.1 | G10: /admire/bpp/planIndexMagAction/queryConstraintIndexReportData | H10: POST | I10: 统推 | J10: /buaa-bpp-analyse/bpp/planIndexMagAction/queryConstraintIndexReportData | N10: restful | O10: buaa_bpp_zxgz_04_ql01 | P10: 内网 | Q10: JSON | R10: 修改 | S10: 否 | T10: 2024-10-24 11:02:23 | U10: 规划全量分析 | V10: buaa-bpp-allAnaly
A11: 9 | B11: buaa-bpp-analyse | C11: 查询约束指标反馈情况汇总信息接口 | D11: 查询各专业报送的规划指标汇总信息 | E11: V1.0.1 | G11: /nlsde/bpp/planIndexMagAction/queryIndexFeedbackSummaryInfo | H11: GET | I11: 统推 | J11: /buaa-bpp-analyse/bpp/planIndexMagAction/queryIndexFeedbackSummaryInfo | N11: restful | O11: buaa_bpp_dtjh_04_ys01 | P11: 内网 | Q11: JSON | R11: 修改 | S11: 否 | T11: 2024-10-24 11:02:23 | U11: 规划约束校核 | V11: buaa-bpp-constraintCheck
A12: 10 | B12: buaa-bpp-analyse | C12: 查询约束指标数据接口 | D12: 查询各专业报送的指标明细数据，支撑后续数据校核。 | E12: V1.0.1 | G12: /buaa/bpp/planIndexMagAction/queryConstraintIndexData | H12: GET | I12: 统推 | J12: /buaa-bpp-analyse/bpp/planIndexMagAction/queryConstraintIndexData | N12: restful | O12: buaa_bpp_dtjh_04_ys02 | P12: 内网 | Q12: JSON | R12: 暂无 | S12: 否 | T12: 2024-10-24 11:02:23 | U12: 规划约束校核 | V12: buaa-bpp-constraintCheck
A13: 11 | B13: buaa-bpp-analyse | C13: 修改约束指标确认状态接口 | D13: 发展部对核对通过的指标进行单个或者批量确认，对核对不通过的指标进行单个或者批量退回。 | E13: V1.0.1 | G13: /admire/bpp/planIndexMagAction/updateConstraintIndexAuditState | H13: GET | I13: 统推 | J13: /buaa-bpp-analyse/bpp/planIndexMagAction/updateConstraintIndexAuditState | N13: restful | O13: buaa_bpp_dtjh_04_ys03 | P13: 内网 | Q13: JSON | R13: 暂无 | S13: 否 | T13: 2024-10-24 11:02:23 | U13: 规划约束校核 | V13: buaa-bpp-constraintCheck
A14: 12 | B14: buaa-bpp-analyse | C14: 取消已确认约束指标接口 | D14: 发展部对已确认的规划指标进行单个或者批量取消确认操作，取消确认后，规划指标可以进行修改、退回。 | E14: V1.0.1 | G14: /nlsde/bpp/planIndexMagAction/cancelConfirmedConstraintIndex | H14: GET | I14: 统推 | J14: /buaa-bpp-analyse/bpp/planIndexMagAction/cancelConfirmedConstraintIndex | N14: restful | O14: buaa_bpp_dtjh_04_ys04 | P14: 内网 | Q14: JSON | R14: 暂无 | S14: 否 | T14: 2024-10-24 11:02:23 | U14: 规划约束校核 | V14: buaa-bpp-constraintCheck
... A1192: 1190 | B1192: buaa-res-uapreport | C1192: 报表服务_报表导出 | D1192: 支撑各业务按照权限、导出类型等导出报表信息 | E1192: v1.0.1 | G1192: /admire/uapreport/com.sgcc.uap.report.run.service.ReportRun/runReport.res | H1192: POST | I1192: 统推 | J1192: /buaa-res-uapreport/uapreport/com.sgcc.uap.report.run.service.ReportRun/runReport.res | N1192: restful | O1192: res_uapreport_runReport | P1192: 内网 | Q1192: JSON | R1192: 导出 | S1192: 否 | T1192: 2024-10-24 11:02:23 | U1192: 项目报表自定义 | V1192: buaa-res-uapreportCustom
A1193: 1191 | B1193: =_xlfn.XLOOKUP(O1193,[2]项目中台接口!$O:$O,[2]项目中台接口!$B:$B) -> pmp-res-uapreport | C1193: 报表服务_树形结构数据导出 | D1193: 支撑按照权限、数据类型等导出树形结构数据 | E1193: v1.0.1 | G1193: /nlsde/uapreport/com.sgcc.uap.report.issue.service.ReportExport/dsData_query.res | H1193: POST | I1193: 统推 | J1193: /buaa-res-uapreport/uapreport/com.sgcc.uap.report.issue.service.ReportExport/dsData_query.res | N1193: restful | O1193: res_uapreport_sxsjcx_02 | P1193: 内网 | Q1193: JSON | R1193: 查询 | S1193: 否 | T1193: 2024-10-24 11:02:23 | U1193: 项目报表自定义 | V1193: buaa-res-uapreportCustom
A1194: 1192 | B1194: =_xlfn.XLOOKUP(O1194,[2]项目中台接口!$O:$O,[2]项目中台接口!$B:$B) -> pmp-res-uapreport | C1194: 报表服务_查询数据 | D1194: 支撑各业务按照权限查询报表列表数据 | E1194: v1.0.1 | G1194: /buaa/uapreport/com.sgcc.uap.report.run.service.ReportRunService/getReportInfoById.res | H1194: POST | I1194: 统推 | J1194: /buaa-res-uapreport/uapreport/com.sgcc.uap.report.run.service.ReportRunService/getReportInfoById.res | N1194: restful | O1194: res_uapreport_sxsjcx_03 | P1194: 内网 | Q1194: JSON | R1194: 查询 | S1194: 否 | T1194: 2024-10-24 11:02:23 | U1194: 项目报表自定义 | V1194: buaa-res-uapreportCustom
A1195: 1193 | B1195: =_xlfn.XLOOKUP(O1195,[2]项目中台接口!$O:$O,[2]项目中台接口!$B:$B) -> pmp-res-uapreport | C1195: 报表服务_数据查询 | D1195: 支撑各业务按照权限查询报表详细数据 | E1195: v1.0.1 | G1195: /admire/uapreport/com.sgcc.uap.report.issue.service.ReportUrl/dsData_query.res | H1195: POST | I1195: 统推 | J1195: /buaa-res-uapreport/uapreport/com.sgcc.uap.report.issue.service.ReportUrl/dsData_query.res | N1195: restful | O1195: res_uapreport_sxsjcx_04 | P1195: 内网 | Q1195: JSON | R1195: 查询 | S1195: 否 | T1195: 2024-10-24 11:02:23 | U1195: 项目报表自定义 | V1195: buaa-res-uapreportCustom
A1196: 1194 | B1196: =_xlfn.XLOOKUP(O1196,[2]项目中台接口!$O:$O,[2]项目中台接口!$B:$B) -> pmp-res-uapreport | C1196: 报表服务_释放资源 | D1196: 支撑运维人员对资源进行管理，对报表资源进行释放 | E1196: v1.0.1 | G1196: /nlsde/uapreport/com.sgcc.uap.report.run.service.ReportManage/getReleaseAllByParentId.res | H1196: POST | I1196: 统推 | J1196: /buaa-res-uapreport/uapreport/com.sgcc.uap.report.run.service.ReportManage/getReleaseAllByParentId.res | N1196: restful | O1196: res_uapreport_sxsjcx_05 | P1196: 内网 | Q1196: JSON | R1196: 查询 | S1196: 否 | T1196: 2024-10-24 11:02:23 | U1196: 项目报表自定义 | V1196: buaa-res-uapreportCustom
A1197: 1195 | B1197: =_xlfn.XLOOKUP(O1197,[2]项目中台接口!$O:$O,[2]项目中台接口!$B:$B) -> pmp-res-uapreport | C1197: 报表服务_查询用户数据 | D1197: 支撑运维人员查询用户报表数据，支撑报表日常运维 | E1197: v1.0.1 | G1197: /buaa/uapreport/com.sgcc.uap.report.sys.service.ResourceAuthority/selectUserObjectTreeDataSource_query.res | H1197: POST | I1197: 统推 | J1197: /buaa-res-uapreport/uapreport/com.sgcc.uap.report.sys.service.ResourceAuthority/selectUserObjectTreeDataSource_query.res | N1197: restful | O1197: res_uapreport_sxsjcx_06 | P1197: 内网 | Q1197: JSON | R1197: 查询 | S1197: 否 | T1197: 2024-10-24 11:02:23 | U1197: 项目报表自定义 | V1197: buaa-res-uapreportCustom
A1198: 1196 | B1198: =_xlfn.XLOOKUP(O1198,[2]项目中台接口!$O:$O,[2]项目中台接口!$B:$B) -> pmp-res-uapreport | C1198: 报表服务_查询报表 | D1198: 支撑各业务按照权限查询报表数据 | E1198: v1.0.1 | G1198: /admire/uapreport/com.sgcc.uap.report.define.service.ReportDefine/selectReport.res | H1198: POST | I1198: 统推 | J1198: /buaa-res-uapreport/uapreport/com.sgcc.uap.report.define.service.ReportDefine/selectReport.res | N1198: restful | O1198: res_uapreport_sxsjcx_07 | P1198: 内网 | Q1198: JSON | R1198: 查询 | S1198: 否 | T1198: 2024-10-24 11:02:23 | U1198: 项目报表自定义 | V1198: buaa-res-uapreportCustom
A1199: 1197 | B1199: =_xlfn.XLOOKUP(O1199,[2]项目中台接口!$O:$O,[2]项目中台接口!$B:$B) -> pmp-res-uapreport | C1199: 报表服务_工具接口 | D1199: 支撑运维人员进行各工具与报表服务集成 | E1199: v1.0.1 | G1199: /nlsde/uapreport/com.sgcc.uap.report.issue.service.ReportUrl/getEngine.res | H1199: POST | I1199: 统推 | J1199: /buaa-res-uapreport/uapreport/com.sgcc.uap.report.issue.service.ReportUrl/getEngine.res | N1199: restful | O1199: res_uapreport_sxsjcx_08 | P1199: 内网 | Q1199: JSON | R1199: 查询 | S1199: 否 | T1199: 2024-10-24 11:02:23 | U1199: 项目报表自定义 | V1199: buaa-res-uapreportCustom
A1200: 1198 | B1200: =_xlfn.XLOOKUP(O1200,[2]项目中台接口!$O:$O,[2]项目中台接口!$B:$B) -> pmp-res-uapreport | C1200: 报表服务_释放通过时间 | D1200: 支撑按照当前登录用户的权限、报表等释放资源等 | E1200: v1.0.1 | G1200: /buaa/uapreport/com.sgcc.uap.report.run.service.ReportRun/getReleaseByTime.res | H1200: POST | I1200: 统推 | J1200: /buaa-res-uapreport/uapreport/com.sgcc.uap.report.run.service.ReportRun/getReleaseByTime.res | N1200: restful | O1200: res_uapreport_sxsjcx_09 | P1200: 内网 | Q1200: JSON | R1200: 查询 | S1200: 否 | T1200: 2024-10-24 11:02:23 | U1200: 项目报表自定义 | V1200: buaa-res-uapreportCustom
A1201: 1199 | B1201: =_xlfn.XLOOKUP(O1201,[2]项目中台接口!$O:$O,[2]项目中台接口!$B:$B) -> pmp-res-uapreport | C1201: 报表服务_查询元数据 | D1201: 支撑按照当前登录用户的权限，获取报表元数据信息 | E1201: v1.0.1 | G1201: /admire/uapreport/com.sgcc.uap.report.sys.service.DatasrcManage/queryMetaData.res | H1201: POST | I1201: 统推 | J1201: /buaa-res-uapreport/uapreport/com.sgcc.uap.report.sys.service.DatasrcManage/queryMetaData.res | N1201: restful | O1201: res_uapreport_sxsjcx_10 | P1201: 内网 | Q1201: JSON | R1201: 查询 | S1201: 否 | T1201: 2024-10-24 11:02:23 | U1201: 项目报表自定义 | V1201: buaa-res-uapreportCustom
A1202: 1200 | B1202: =_xlfn.XLOOKUP(O1202,[2]项目中台接口!$O:$O,[2]项目中台接口!$B:$B) -> pmp-res-uapreport | C1202: 报表服务_新增分组信息 | D1202: 支撑按照部门、公司等新增授权分组信息 | E1202: v1.0.1 | G1202: /nlsde/uapreport/com.sgcc.uap.report.sys.service.ResourceAuthority/insertGroupInfo.res | H1202: POST | I1202: 统推 | J1202: /buaa-res-uapreport/uapreport/com.sgcc.uap.report.sys.service.ResourceAuthority/insertGroupInfo.res | N1202: restful | O1202: res_uapreport_sxsjcx_11 | P1202: 内网 | Q1202: JSON | R1202: 新增 | S1202: 否 | T1202: 2024-10-24 11:02:23 | U1202: 项目报表自定义 | V1202: buaa-res-uapreportCustom
A1203: 1201 | B1203: =_xlfn.XLOOKUP(O1203,[2]项目中台接口!$O:$O,[2]项目中台接口!$B:$B) -> pmp-res-uapreport | C1203: 报表服务_获得登录单位名称 | D1203: 支撑获得登录人及所属单位名称信息 | E1203: v1.0.1 | G1203: /buaa/uapreport/com.sgcc.uap.report.run.service.ReportRun/getDeptName.res | H1203: POST | I1203: 统推 | J1203: /buaa-res-uapreport/uapreport/com.sgcc.uap.report.run.service.ReportRun/getDeptName.res | N1203: restful | O1203: res_uapreport_sxsjcx_12 | P1203: 内网 | Q1203: JSON | R1203: 查询 | S1203: 否 | T1203: 2024-10-24 11:02:23 | U1203: 项目报表自定义 | V1203: buaa-res-uapreportCustom
A1204: 1202 | B1204: =_xlfn.XLOOKUP(O1204,[2]项目中台接口!$O:$O,[2]项目中台接口!$B:$B) -> pmp-res-uapreport | C1204: 报表服务_通过类型查询元数据 | D1204: 支撑各业务通过报表类型查询报表基础信息 | E1204: v1.0.1 | G1204: /admire/uapreport/com.sgcc.uap.report.sys.service.ResourceAuthority/getMetaDataByType.res | H1204: POST | I1204: 统推 | J1204: /buaa-res-uapreport/uapreport/com.sgcc.uap.report.sys.service.ResourceAuthority/getMetaDataByType.res | N1204: restful | O1204: res_uapreport_sxsjcx_13 | P1204: 内网 | Q1204: JSON | R1204: 查询 | S1204: 否 | T1204: 2024-10-24 11:02:23 | U1204: 项目报表自定义 | V1204: buaa-res-uapreportCustom
... A1238: 1236 | B1238: =_xlfn.XLOOKUP(O1238,[2]项目中台接口!$O:$O,[2]项目中台接口!$B:$B) -> #N/A | C1238: 查询项目流转文件信息接口 | D1238: 支撑业务按照专项、文件类型等查询各专项OA公文流转信息 | E1238: v1.0.1 | G1238: /nlsde/res/pmpFile/queryOaItemFile | H1238: POST | I1238: 统推 | J1238: /buaa-res-file/res/buaaFile/queryOaItemFile | N1238: restful | O1238: buaa_res_fjjx_031 | P1238: 内网 | Q1238: JSON | R1238: 暂无 | S1238: 否 | T1238: 2024-10-24 11:02:23 | U1238: 项目文件上传下载 | V1238: buaa-res-fileUpDownload
A1239: 1237 | B1239: buaa-res-file | C1239: 上传项目文件接口 | D1239: 按照关联项目的文件和不关联项目的文件两种形式，提供各专项上传相关文件的能力。 | E1239: v1.0.1 | G1239: /buaa/res/pmpFile/uploadDocument | H1239: POST | I1239: 统推 | J1239: /buaa-res-file/res/buaaFile/uploadDocument | N1239: RESTFUL | O1239: buaa_res_fjjx_040 | P1239: 内网 | Q1239: JSON | R1239: 暂无 | S1239: 否 | T1239: 2025-01-03 10:46:14 | U1239: 项目文件上传下载 | V1239: buaa-res-fileUpDownload
A1240: 1238 | B1240: buaa-res-file | C1240: 下载项目文件接口 | D1240: 按照传入的文件ID、所属单位、所属部门、操作人等信息，下载各专项文件。 | E1240: v1.0.1 | G1240: /admire/res/pmpFile/downloadDocument | H1240: POST | I1240: 统推 | J1240: /buaa-res-file/res/buaaFile/downloadDocument | N1240: RESTFUL | O1240: buaa_res_fjjx_041 | P1240: 内网 | Q1240: JSON | R1240: 暂无 | S1240: 否 | T1240: 2025-01-03 10:46:14 | U1240: 项目文件上传下载 | V1240: buaa-res-fileUpDownload
A1241: 1239 | B1241: buaa-res-file | C1241: 查询项目关联文件信息接口 | D1241: 按照项目编码、项目ID、文件类型、所属业务阶段、专项类型等查询条件，查询项目相关文件信息。 | E1241: v1.0.1 | G1241: /nlsde/res/pmpFile/queryItemRela | H1241: POST | I1241: 统推 | J1241: /buaa-res-file/res/buaaFile/queryItemRela | N1241: RESTFUL | O1241: buaa_res_fjjx_042 | P1241: 内网 | Q1241: JSON | R1241: 暂无 | S1241: 否 | T1241: 2025-01-03 10:46:14 | U1241: 项目文件上传下载 | V1241: buaa-res-fileUpDownload
A1242: 1240 | B1242: =_xlfn.XLOOKUP(O1242,[2]项目中台接口!$O:$O,[2]项目中台接口!$B:$B) -> #N/A | C1242: 公文与项目关联接口 | D1242: 支撑各专项按照项目阶段、文件类型、项目等信息，进行公文与项目关联 | E1242: v1.0.1 | G1242: /buaa/oaAction/documentRelaItem | H1242: POST | I1242: 统推 | J1242: /buaa-res-file/oaAction/documentRelaItem | N1242: restful | O1242: buaa_res_gxgl_003 | P1242: 内网 | Q1242: JSON | R1242: 暂无 | S1242: 否 | T1242: 2024-10-24 11:02:23 | U1242: 项目文件上传下载 | V1242: buaa-res-fileUpDownload
A1243: 1241 | B1243: =_xlfn.XLOOKUP(O1243,[2]项目中台接口!$O:$O,[2]项目中台接口!$B:$B) -> #N/A | C1243: 公文与项目解除关联接口 | D1243: 支撑各专项进行OA系统流转的公文与项目关系解除关联 | E1243: v1.0.1 | G1243: /admire/oaAction/cancelRelaItem | H1243: POST | I1243: 统推 | J1243: /buaa-res-file/oaAction/cancelRelaItem | N1243: restful | O1243: buaa_res_gxjc_004 | P1243: 内网 | Q1243: JSON | R1243: 暂无 | S1243: 否 | T1243: 2024-10-24 11:02:23 | U1243: 项目文件上传下载 | V1243: buaa-res-fileUpDownload
A1244: 1242 | B1244: =_xlfn.XLOOKUP(O1244,[2]项目中台接口!$O:$O,[2]项目中台接口!$B:$B) -> #N/A | C1244: 公文与项目关联信息查询接口 | D1244: 支撑按照专项、所属公司、文件类型等，查询公文与项目关联信息 | E1244: v1.0.1 | G1244: /nlsde/oaAction/getItemRela | H1244: POST | I1244: 统推 | J1244: /buaa-res-file/oaAction/getItemRela | N1244: restful | O1244: buaa_res_gxxc_002 | P1244: 内网 | Q1244: JSON | R1244: 暂无 | S1244: 否 | T1244: 2024-10-24 11:02:23 | U1244: 项目文件上传下载 | V1244: buaa-res-fileUpDownload
A1245: 1243 | B1245: =_xlfn.XLOOKUP(O1245,[2]项目中台接口!$O:$O,[2]项目中台接口!$B:$B) -> #N/A | C1245: 支撑综合计划查询专项文件接口 | D1245: 支撑各系统按照专项、项目阶段等查询专项项目与文件的关系 | E1245: v1.0.1 | G1245: /buaa/res/pmpFile/query/getFileDesc | H1245: POST | I1245: 统推 | J1245: /buaa-res-file/res/buaaFile/query/getFileDesc | N1245: restful | O1245: buaa_res_rzpz_018 | P1245: 内网 | Q1245: JSON | R1245: 暂无 | S1245: 否 | T1245: 2024-10-24 11:02:23 | U1245: 项目文件上传下载 | V1245: buaa-res-fileUpDownload
A1246: 1244 | B1246: =_xlfn.XLOOKUP(O1246,[2]项目中台接口!$O:$O,[2]项目中台接口!$B:$B) -> #N/A | C1246: 通过问题获取知识 | D1246: 提供依据输入问题，智能匹配已有知识并输出的服务，可支撑业务快速拿到自己想要的获取的知识 | E1246: v1.0.1 | G1246: /admire/qa/gouxuan/dialog/talk | H1246: POST | I1246: 统推 | J1246: /buaa-res-graph/qa/gouxuan/dialog/talk | N1246: restful | O1246: buaa_res_zswd_014 | P1246: 内网 | Q1246: JSON | R1246: 暂无 | S1246: 否 | T1246: 2024-10-24 11:02:23 | U1246: 项目智能检索 | V1246: buaa-res-intelligentRetrieval
A1247: 1245 | B1247: =_xlfn.XLOOKUP(O1247,[2]项目中台接口!$O:$O,[2]项目中台接口!$B:$B) -> #N/A | C1247: 通过知识ID获取知识详情 | D1247: 支撑16个专项通过知识ID获取知识详情，根据知识ID进行所属的详情信息的查询。 | E1247: v1.0.1 | G1247: /nlsde/qa/gouxuan/text_intelli/common/search_spo_by_sid | H1247: POST | I1247: 统推 | J1247: /buaa-res-graph/qa/gouxuan/text_intelli/common/search_spo_by_sid | N1247: restful | O1247: buaa_res_zswd_016 | P1247: 内网 | Q1247: JSON | R1247: 暂无 | S1247: 否 | T1247: 2024-10-24 11:02:23 | U1247: 项目智能检索 | V1247: buaa-res-intelligentRetrieval
A1248: 1246 | B1248: =_xlfn.XLOOKUP(O1248,[2]项目中台接口!$O:$O,[2]项目中台接口!$B:$B) -> #N/A | C1248: 物资pmo服务 | D1248: 物资pmo服务，通过汇总项目信息数据同步给ERP，满足各省与直属单位进行对应的数据上报。 | E1248: v1.0.1 | G1248: /buaa/supplyService/SupplyService | H1248: POST | I1248: 统推 | J1248: /buaa-res-prjinfo/supplyService/SupplyService | N1248: restful | O1248: buaa_res_buaao_01 | P1248: 内网 | Q1248: JSON | R1248: 查询 | S1248: 否 | T1248: 2024-10-24 11:02:23 | U1248: 项目信息查询 | V1248: buaa-res-informationService
A1249: 1247 | B1249: =_xlfn.XLOOKUP(O1249,[2]项目中台接口!$O:$O,[2]项目中台接口!$B:$B) -> #N/A | C1249: 文件审批信息查询接口 | D1249: 支撑各业务计划年份、所属阶段等查询项目文件审批信息 | E1249: v1.0.1 | G1249: /admire/oaAction/getItemFileInfo | H1249: POST | I1249: 统推 | J1249: /buaa-res-prjinfo/oaAction/getItemFileInfo | N1249: restful | O1249: buaa_res_wsxc_001 | P1249: 内网 | Q1249: JSON | R1249: 暂无 | S1249: 否 | T1249: 2024-10-24 11:02:23 | U1249: 项目信息查询 | V1249: buaa-res-informationService
A1250: 1248 | B1250: =_xlfn.XLOOKUP(O1250,[2]项目中台接口!$O:$O,[2]项目中台接口!$B:$B) -> #N/A | C1250: 查询电网基建项目信息 | D1250: 支撑按照计划年份、所属阶段等查询电网基建项目明细信息 | E1250: v1.0.1 | G1250: /nlsde/resPrjinfo/getDWJJDataList | H1250: POST | I1250: 统推 | J1250: /buaa-res-prjinfo/resPrjinfo/getDWJJDataList | N1250: restful | O1250: buaa_res_xmxxc_31 | P1250: 内网 | Q1250: JSON | R1250: 暂无 | S1250: 否 | T1250: 2024-10-24 11:02:23 | U1250: 项目信息查询 | V1250: buaa-res-informationService
...

Sheet 出入参信息(新增)
A1: 序号 | B1: *接口中文名 | C1: 接口编码 （ID/唯一标识） | D1: *接口入参 | E1: *入参示例 | F1: *接口出参 | G1: *出参示例
A2: 说明 | B2: 和接口sheet中接口中文名保持一致 | C2: 和接口sheet中接口编码保持一致 | D2: 接口入参Json串，具体格式要求详见(出入参Json串格式模板说明)sheet页 | E2: 入参示例说明 | F2: 接口入参Json串，具体格式要求详见(出入参Json串格式模板说明)sheet页 | G2: 出参示例说明
A3: 示例 | B3: 专项投资测算结果查询接口 | C3: 例旧：buaap_sj_zxtzcsjgcx_001 新增：dwywzyzt_qxzx-000001 | D3: [{"default":"查询条件","name":"filters","length":"","reqType":"3","type":"object","required":true,"desc":"查询条件","child":[{"default":"设备型号","name":"model","length":"42","reqType":"3","type":"string","required":false,"desc":"设备型号","child":[]}, {"default":"检测试验项目ID","name":"testItemId","length":"","reqType":"3","type":"string","required":false,"desc":"检测试验项目ID","child":[]}, {"default":"检测试验项目编码","name":"testItemCode","length":"","reqType":"3","type":"string","required":true,"desc":"检测试验项目编码","child":[]}, {"default":"源端系统中设备类型编码","name":"sourceEquipTypeCode","length":"42","reqType":"3","type":"string","required":true,"desc":"源端系统中设备类型编码","child":[]}, {"default":"设备类型编码标识","name":"equipTpyeFlag","length":"2","reqType":"3","type":"int","required":false,"desc":"设备类型编码标识","child":[]}, {"default":"部门标识","name":"department","length":"42","reqType":"3","type":"string","required":false,"desc":"部门标识","child":[]}, {"default":"检测试验专业编码","name":"testMajorCode","length":"","reqType":"3","type":"array","required":false,"desc":"检测试验专业编码","child":[]}, {"default":"检测试验性质编码","name":"testNatureCode","length":"","reqType":"3","type":"array","required":false,"desc":"检测试验性质编码","child":[]}, {"default":"标签编码列表","name":"tagCodeList","length":"","reqType":"3","type":"array","required":false,"desc":"标签编码列表","child":[]}, {"default":"是否查询逻辑删除数据","name":"allFlag","length":"2","reqType":"3","type":"int","required":false,"desc":"是否查询逻辑删除数据","child":[]}]}, {"default":"页数","name":"page","length":"10","reqType":"3","type":"int","required":false,"desc":"页数","child":[]}, {"default":"每页中条数","name":"perPage","length":"10","reqType":"3","type":"int","required":false,"desc":"每页中条数","child":[]}] | E3: { "filters": { "model": "", "tagCodeList": [], "testItemId": "", "testItemCode": "JLBYQ-SYZY-01-0005", "sourceEquipTypeCode": "JLBYQ", "department": "", "testMajorCode": [], "testNatureCode": [], "allFlag": "1" }, "page": 1, "perPage": 200 } | F3: [{"default":"","name":"errors","length":"200","type":"string","desc":"错误信息","child":[]}, {"default":"","name":"message","length":"200","type":"string","desc":"返回描述","child":[]}, {"default":"","name":"status","length":"10","type":"string","desc":"状态码","child":[]}, {"default":"","name":"result","length":"","type":"object","desc":"结果数据","child":[{"default":"","name":"current","length":"","type":"int","desc":"页号","child":[]}, {"default":"","name":"size","length":"","type":"int","desc":"页大小","child":[]}, {"default":"","name":"pages","length":"","type":"int","desc":"总页数","child":[]}, {"default":"","name":"total","length":"","type":"int","desc":"总记录数","child":[]}, {"default":"","name":"records","length":"","type":"array","desc":"分页数据对象","child":[]}]}] | G3: { "code": "000000", "message": "success", "data": { "current": 1, "size": 200, "pages": 1, "total": 1, "records": [ { "testItemInfo": { "id": "27068c1f194a11ee946e000c2904bb89", "code": "JLBYQ-SYZY-01-0005", "name": "交流变压器超声波(接触式)局放检测", "description": "", "majorCode": "SYZY-01", "majorName": "带电检测", "equipTypeId": "a4fec00b6a7026c04d4144bde7299941", "equipTypeCode": "JLBYQ", "componentsTypeId": "b485a5f8e8ff80808188b485a50188b485a5f70000", "componentsTypeCode": "COMPONENT-0006", "astLimitationDescription": "", "tagInfoList": [ { "tagTypeCode": "TAG-0019", "tagTypeName": "电压等级", "tagList": [ { "tagCode": "TAG-0019-02", "tagName": "35kV" }, { "tagCode": "TAG-0019-03", "tagName": "66kV" }, { "tagCode": "TAG-0019-04", "tagName": "110kV" }, { "tagCode": "TAG-0019-05", "tagName": "220kV" }, { "tagCode": "TAG-0019-06", "tagName": "330kV" }, { "tagCode": "TAG-0019-07", "tagName": "500kV" }, { "tagCode": "TAG-0019-08", "tagName": "750kV" }, { "tagCode": "TAG-0019-09", "tagName": "1000kV" } ] } ], "testNatureList": [ { "testNatureCode": "SYXZ-02", "testNatureName": "出厂试验" }, { "testNatureCode": "SYXZ-04", "testNatureName": "交接试验" }, { "testNatureCode": "SYXZ-05", "testNatureName": "例行试验" }, { "testNatureCode": "SYXZ-06", "testNatureName": "诊断试验" } ], "canExpand": 1, "canMultiple": null, "deviceCodeList": [], "deleteMark": 0 }, "subitemList": [ { "id": "97a9aa2cbc2c9583108a92a89f018a97a9a9830150", "code": "JLBYQ-SYZY-01-0005-SUBITEM-0001", "name": "局放量测试值(有效值)", "description": "", "testItemId": "27068c1f194a11ee946e000c2904bb89", "isCalculate": 0, "expressionDescription": "", "resultType": "1", "checkStandard": "", "astLimitationDescription": "", "conditionList": [], "natureCodes": null, "unitId": "6cea0712e7336e383c24b3955bad5297", "unitName": "分贝/毫伏", "unitCode": "JL-0313", "unitSymbol": "dB/mV", "tagInfoList": [], "deleteMark": 0 }, { "id": "b4252371194d11ee946e000c2904bb89", "code": "JLBYQ-SYZY-01-0005-SUBITEM-0002", "name": "局放量测试值(峰值)", "description": "", "testItemId": "27068c1f194a11ee946e000c2904bb89", "isCalculate": 0, "expressionDescription": "", "resultType": "1", "checkStandard": "", "astLimitationDescription": "", "conditionList": [], "natureCodes": null, "unitId": "6cea0712e7336e383c24b3955bad5297", "unitName": "分贝/毫伏", "unitCode": "JL-0313", "unitSymbol": "dB/mV", "tagInfoList": [], "deleteMark": 0 }, { "id": "97aa4f780e2c9583108a92a89f018a97aa4ece0152", "code": "JLBYQ-SYZY-01-0005-SUBITEM-0003", "name": "50Hz相关性", "description": "", "testItemId": "27068c1f194a11ee946e000c2904bb89", "isCalculate": 0, "expressionDescription": "", "resultType": "1", "checkStandard": "", "astLimitationDescription": "", "conditionList": [], "natureCodes": null, "unitId": "6cea0712e7336e383c24b3955bad5297", "unitName": "分贝/毫伏", "unitCode": "JL-0313", "unitSymbol": "dB/mV", "tagInfoList": [], "deleteMark": 0 }, { "id": "97aae5e27e2c9583108a92a89f018a97aae5370154", "code": "JLBYQ-SYZY-01-0005-SUBITEM-0004", "name": "100Hz相关性", "description": "", "testItemId": "27068c1f194a11ee946e000c2904bb89", "isCalculate": 0, "expressionDescription": "", "resultType": "1", "checkStandard": "", "astLimitationDescription": "", "conditionList": [], "natureCodes": null, "unitId": "6cea0712e7336e383c24b3955bad5297", "unitName": "分贝/毫伏", "unitCode": "JL-0313", "unitSymbol": "dB/mV", "tagInfoList": [], "deleteMark": 0 }, { "id": "b425234e194d11ee946e000c2904bb89", "code": "JLBYQ-SYZY-01-0005-SUBITEM-0005", "name": "图谱文件", "description": "", "testItemId": "27068c1f194a11ee946e000c2904bb89", "isCalculate": 0, "expressionDescription": "", "resultType": "8", "checkStandard": "", "astLimitationDescription": "", "conditionList": [], "natureCodes": null, "unitId": "378d580fc0f218422fe4b25b10e1b93b", "unitName": "不限格式", "unitCode": "JL-0083", "unitSymbol": "-", "tagInfoList": [], "deleteMark": 0 }, { "id": "a115c70db98a5e81538a9bd7de018aa115c6b600ac", "code": "JLBYQ-SYZY-01-0005-SUBITEM-0006", "name": "特征分析", "description": "", "testItemId": "27068c1f194a11ee946e000c2904bb89", "isCalculate": 0, "expressionDescription": "", "resultType": "3", "checkStandard": "有放电和无放电", "astLimitationDescription": "", "conditionList": [], "natureCodes": null, "unitId": "0ef6575587c7cc8b2bb9d969392df1f3", "unitName": "无单位", "unitCode": "JL-0271", "unitSymbol": "-", "tagInfoList": [], "deleteMark": 0 } ], "partsTypeList": [ { "id": "258f529a194c11ee946e000c2904bb89", "code": "JLBYQ-SYZY-01-0005-POS-02", "name": " 油(气)箱体", "fid": "", "fname": "", "testItemId": "27068c1f194a11ee946e000c2904bb89", "deleteMark": 0, "partsList": [ { "id": "1f0228f8194c11ee946e000c2904bb89", "code": "JLBYQ-SYZY-01-0005-POS-02-001", "name": " 油(气)箱体左侧", "testPartsTypeId": "258f529a194c11ee946e000c2904bb89", "testPartsTypeCode": "JLBYQ-SYZY-01-0005-POS-02", "astLimitationDescription": "", "priorityLevel": 1, "natureCodes": null, "deleteMark": 0, "tagInfoList": null }, { "id": "1f022909194c11ee946e000c2904bb89", "code": "JLBYQ-SYZY-01-0005-POS-02-002", "name": " 油(气)箱体右侧", "testPartsTypeId": "258f529a194c11ee946e000c2904bb89", "testPartsTypeCode": "JLBYQ-SYZY-01-0005-POS-02", "astLimitationDescription": "", "priorityLevel": 2, "natureCodes": null, "deleteMark": 0, "tagInfoList": null }, { "id": "1f02288e194c11ee946e000c2904bb89", "code": "JLBYQ-SYZY-01-0005-POS-02-003", "name": " 油(气)箱体正面", "testPartsTypeId": "258f529a194c11ee946e000c2904bb89", "testPartsTypeCode": "JLBYQ-SYZY-01-0005-POS-02", "astLimitationDescription": "", "priorityLevel": 3, "natureCodes": null, "deleteMark": 0, "tagInfoList": null }, { "id": "1f0228e1194c11ee946e000c2904bb89", "code": "JLBYQ-SYZY-01-0005-POS-02-004", "name": " 油(气)箱体背面", "testPartsTypeId": "258f529a194c11ee946e000c2904bb89", "testPartsTypeCode": "JLBYQ-SYZY-01-0005-POS-02", "astLimitationDescription": "", "priorityLevel": 4, "natureCodes": null, "deleteMark": 0, "tagInfoList": null } ], "fcode": "" }, { "id": "258f52ad194c11ee946e000c2904bb89", "code": "JLBYQ-SYZY-01-0005-POS-01", "name": "测点个数", "fid": "258f529a194c11ee946e000c2904bb89", "fname": " 油(气)箱体", "testItemId": "27068c1f194a11ee946e000c2904bb89", "deleteMark": 0, "partsList": [ { "id": "1f0229dd194c11ee946e000c2904bb89", "code": "JLBYQ-SYZY-01-0005-POS-01-001", "name": "测点1", "testPartsTypeId": "258f52ad194c11ee946e000c2904bb89", "testPartsTypeCode": "JLBYQ-SYZY-01-0005-POS-01", "astLimitationDescription": "", "priorityLevel": 1, "natureCodes": null, "deleteMark": 0, "tagInfoList": null }, { "id": "1f0229ef194c11ee946e000c2904bb89", "code": "JLBYQ-SYZY-01-0005-POS-01-002", "name": "测点2", "testPartsTypeId": "258f52ad194c11ee946e000c2904bb89", "testPartsTypeCode": "JLBYQ-SYZY-01-0005-POS-01", "astLimitationDescription": "", "priorityLevel": 2, "natureCodes": null, "deleteMark": 0, "tagInfoList": null }, { "id": "1f022a00194c11ee946e000c2904bb89", "code": "JLBYQ-SYZY-01-0005-POS-01-003", "name": "测点3", "testPartsTypeId": "258f52ad194c11ee946e000c2904bb89", "testPartsTypeCode": "JLBYQ-SYZY-01-0005-POS-01", "astLimitationDescription": "", "priorityLevel": 3, "natureCodes": null, "deleteMark": 0, "tagInfoList": null }, { "id": "1f022a11194c11ee946e000c2904bb89", "code": "JLBYQ-SYZY-01-0005-POS-01-004", "name": "测点4", "testPartsTypeId": "258f52ad194c11ee946e000c2904bb89", "testPartsTypeCode": "JLBYQ-SYZY-01-0005-POS-01", "astLimitationDescription": "", "priorityLevel": 4, "natureCodes": null, "deleteMark": 0, "tagInfoList": null }, { "id": "1f022a22194c11ee946e000c2904bb89", "code": "JLBYQ-SYZY-01-0005-POS-01-005", "name": "测点5", "testPartsTypeId": "258f52ad194c11ee946e000c2904bb89", "testPartsTypeCode": "JLBYQ-SYZY-01-0005-POS-01", "astLimitationDescription": "", "priorityLevel": 5, "natureCodes": null, "deleteMark": 0, "tagInfoList": null }, { "id": "1f022a33194c11ee946e000c2904bb89", "code": "JLBYQ-SYZY-01-0005-POS-01-006", "name": "测点6", "testPartsTypeId": "258f52ad194c11ee946e000c2904bb89", "testPartsTypeCode": "JLBYQ-SYZY-01-0005-POS-01", "astLimitationDescription": "", "priorityLevel": 6, "natureCodes": null, "deleteMark": 0, "tagInfoList": null }, { "id": "1f022a44194c11ee946e000c2904bb89", "code": "JLBYQ-SYZY-01-0005-POS-01-007", "name": "测点7", "testPartsTypeId": "258f52ad194c11ee946e000c2904bb89", "testPartsTypeCode": "JLBYQ-SYZY-01-0005-POS-01", "astLimitationDescription": "", "priorityLevel": 7, "natureCodes": null, "deleteMark": 0, "tagInfoList": null }, { "id": "1f02292d194c11ee946e000c2904bb89", "code": "JLBYQ-SYZY-01-0005-POS-01-008", "name": "测点8", "testPartsTypeId": "258f52ad194c11ee946e000c2904bb89", "testPartsTypeCode": "JLBYQ-SYZY-01-0005-POS-01", "astLimitationDescription": "", "priorityLevel": 8, "natureCodes": null, "deleteMark": 0, "tagInfoList": null }, { "id": "1f02293e194c11ee946e000c2904bb89", "code": "JLBYQ-SYZY-01-0005-POS-01-009", "name": "测点9", "testPartsTypeId": "258f52ad194c11ee946e000c2904bb89", "testPartsTypeCode": "JLBYQ-SYZY-01-0005-POS-01", "astLimitationDescription": "", "priorityLevel": 9, "natureCodes": null, "deleteMark": 0, "tagInfoList": null } ], "fcode": "JLBYQ-SYZY-01-0005-POS-02" } ], "auxRecordList": [ { "id": "097b2c2fa8a89457cca3871ba99bd7a6", "name": "试验天气", "code": "weather", "description": "", "unitCode": null, "unitId": null, "unitName": null, "unitSymbol": null, "resultType": "3" }, { "id": "2f46e9e985f65a886a68b3b62fdb36c5", "name": "环境温度", "code": "Enviroment_Temperature", "description": "", "unitCode": "JL-0107", "unitId": "8becd4d21180929e537ddd1d1d4a31e6", "unitName": "度", "unitSymbol": "°C", "resultType": "3" }, { "id": "075791a68bf2fcbbd210ac0579d134dc", "name": "试验日期", "code": "time", "description": "", "unitCode": null, "unitId": null, "unitName": null, "unitSymbol": null, "resultType": "3" }, { "id": "a27de730f55ff3d9dda0f523c688620e", "name": "相对湿度", "code": "relative_humidity", "description": "相对湿度", "unitCode": "JL-0219", "unitId": "64c3841293d051f3b4a00899dc507a75", "unitName": "百分比", "unitSymbol": "％", "resultType": "3" } ], "testSubitemAndPartList": [ { "testItemId": "27068c1f194a11ee946e000c2904bb89", "testItemCode": "JLBYQ-SYZY-01-0005", "testItemName": "交流变压器超声波(接触式)局放检测", "subItemId": "97a9aa2cbc2c9583108a92a89f018a97a9a9830150", "subItemCode": "JLBYQ-SYZY-01-0005-SUBITEM-0001", "subItemName": "局放量测试值(有效值)", "conditionId": null, "conditionCode": null, "conditionName": null, "partsTypeId": "258f52ad194c11ee946e000c2904bb89", "partsTypeCode": "JLBYQ-SYZY-01-0005-POS-01", "partsTypeName": "测点个数", "testPartId": "1f02292d194c11ee946e000c2904bb89", "testPartCode": "JLBYQ-SYZY-01-0005-POS-01-008", "testPartName": "测点8", "fpartid": "1f02288e194c11ee946e000c2904bb89", "fpartCode": "JLBYQ-SYZY-01-0005-POS-02-003", "fpartName": " 油(气)箱体正面" }, { "testItemId": "27068c1f194a11ee946e000c2904bb89", "testItemCode": "JLBYQ-SYZY-01-0005", "testItemName": "交流变压器超声波(接触式)局放检测", "subItemId": "97a9aa2cbc2c9583108a92a89f018a97a9a9830150", "subItemCode": "JLBYQ-SYZY-01-0005-SUBITEM-0001", "subItemName": "局放量测试值(有效值)", "conditionId": null, "conditionCode": null, "conditionName": null, "partsTypeId": "258f52ad194c11ee946e000c2904bb89", "partsTypeCode": "JLBYQ-SYZY-01-0005-POS-01", "partsTypeName": "测点个数", "testPartId": "1f02292d194c11ee946e000c2904bb89", "testPartCode": "JLBYQ-SYZY-01-0005-POS-01-008", "testPartName": "测点8", "fpartid": "1f0228e1194c11ee946e000c2904bb89", "fpartCode": "JLBYQ-SYZY-01-0005-POS-02-004", "fpartName": " 油(气)箱体背面" }, { "testItemId": "27068c1f194a11ee946e000c2904bb89", "testItemCode": "JLBYQ-SYZY-01-0005", "testItemName": "交流变压器超声波(接触式)局放检测", "subItemId": "b4252371194d11ee946e000c2904bb89", "subItemCode": "JLBYQ-SYZY-01-0005-SUBITEM-0002", "subItemName": "局放量测试值(峰值)", "conditionId": null, "conditionCode": null, "conditionName": null, "partsTypeId": "258f52ad194c11ee946e000c2904bb89", "partsTypeCode": "JLBYQ-SYZY-01-0005-POS-01", "partsTypeName": "测点个数", "testPartId": "1f022b12194c11ee946e000c2904bb89", "testPartCode": "JLBYQ-SYZY-01-0005-POS-01-027", "testPartName": "测点27", "fpartid": "1f02288e194c11ee946e000c2904bb89", "fpartCode": "JLBYQ-SYZY-01-0005-POS-02-003", "fpartName": " 油(气)箱体正面" }, { "testItemId": "27068c1f194a11ee946e000c2904bb89", "testItemCode": "JLBYQ-SYZY-01-0005", "testItemName": "交流变压器超声波(接触式)局放检测", "subItemId": "b4252371194d11ee946e000c2904bb89", "subItemCode": "JLBYQ-SYZY-01-0005-SUBITEM-0002", "subItemName": "局放量测试值(峰值)", "conditionId": null, "conditionCode": null, "conditionName": null, "partsTypeId": "258f52ad194c11ee946e000c2904bb89", "partsTypeCode": "JLBYQ-SYZY-01-0005-POS-01", "partsTypeName": "测点个数", "testPartId": "1f022b12194c11ee946e000c2904bb89", "testPartCode": "JLBYQ-SYZY-01-0005-POS-01-027", "testPartName": "测点27", "fpartid": "1f0228e1194c11ee946e000c2904bb89", "fpartCode": "JLBYQ-SYZY-01-0005-POS-02-004", "fpartName": " 油(气)箱体背面" }, { "testItemId": "27068c1f194a11ee946e000c2904bb89", "testItemCode": "JLBYQ-SYZY-01-0005", "testItemName": "交流变压器超声波(接触式)局放检测", "subItemId": "b4252371194d11ee946e000c2904bb89", "subItemCode": "JLBYQ-SYZY-01-0005-SUBITEM-0002", "subItemName": "局放量测试值(峰值)", "conditionId": null, "conditionCode": null, "conditionName": null, "partsTypeId": "258f52ad194c11ee946e000c2904bb89", "partsTypeCode": "JLBYQ-SYZY-01-0005-POS-01", "partsTypeName": "测点个数", "testPartId": "1f022b12194c11ee946e000c2904bb89", "testPartCode": "JLBYQ-SYZY-01-0005-POS-01-027", "testPartName": "测点27", "fpartid": "1f0228f8194c11ee946e000c2904bb89", "fpartCode": "JLBYQ-SYZY-01-0005-POS-02-001", "fpartName": " 油(气)箱体左侧" }, { "testItemId": "27068c1f194a11ee946e000c2904bb89", "testItemCode": "JLBYQ-SYZY-01-0005", "testItemName": "交流变压器超声波(接触式)局放检测", "subItemId": "b4252371194d11ee946e000c2904bb89", "subItemCode": "JLBYQ-SYZY-01-0005-SUBITEM-0002", "subItemName": "局放量测试值(峰值)", "conditionId": null, "conditionCode": null, "conditionName": null, "partsTypeId": "258f52ad194c11ee946e000c2904bb89", "partsTypeCode": "JLBYQ-SYZY-01-0005-POS-01", "partsTypeName": "测点个数", "testPartId": "1f022b12194c11ee946e000c2904bb89", "testPartCode": "JLBYQ-SYZY-01-0005-POS-01-027", "testPartName": "测点27", "fpartid": "1f022909194c11ee946e000c2904bb89", "fpartCode": "JLBYQ-SYZY-01-0005-POS-02-002", "fpartName": " 油(气)箱体右侧" }, { "testItemId": "27068c1f194a11ee946e000c2904bb89", "testItemCode": "JLBYQ-SYZY-01-0005", "testItemName": "交流变压器超声波(接触式)局放检测", "subItemId": "b4252371194d11ee946e000c2904bb89", "subItemCode": "JLBYQ-SYZY-01-0005-SUBITEM-0002", "subItemName": "局放量测试值(峰值)", "conditionId": null, "conditionCode": null, "conditionName": null, "partsTypeId": "258f52ad194c11ee946e000c2904bb89", "partsTypeCode": "JLBYQ-SYZY-01-0005-POS-01", "partsTypeName": "测点个数", "testPartId": "1f022b23194c11ee946e000c2904bb89", "testPartCode": "JLBYQ-SYZY-01-0005-POS-01-030", "testPartName": "测点30", "fpartid": "1f02288e194c11ee946e000c2904bb89", "fpartCode": "JLBYQ-SYZY-01-0005-POS-02-003", "fpartName": " 油(气)箱体正面" }, { "testItemId": "27068c1f194a11ee946e000c2904bb89", "testItemCode": "JLBYQ-SYZY-01-0005", "testItemName": "交流变压器超声波(接触式)局放检测", "subItemId": "b4252371194d11ee946e000c2904bb89", "subItemCode": "JLBYQ-SYZY-01-0005-SUBITEM-0002", "subItemName": "局放量测试值(峰值)", "conditionId": null, "conditionCode": null, "conditionName": null, "partsTypeId": "258f52ad194c11ee946e000c2904bb89", "partsTypeCode": "JLBYQ-SYZY-01-0005-POS-01", "partsTypeName": "测点个数", "testPartId": "1f022b23194c11ee946e000c2904bb89", "testPartCode": "JLBYQ-SYZY-01-0005-POS-01-030", "testPartName": "测点30", "fpartid": "1f0228e1194c11ee946e000c2904bb89", "fpartCode": "JLBYQ-SYZY-01-0005-POS-02-004", "fpartName": " 油(气)箱体背面" }, { "testItemId": "27068c1f194a11ee946e000c2904bb89", "testItemCode": "JLBYQ-SYZY-01-0005", "testItemName": "交流变压器超声波(接触式)局放检测", "subItemId": "b4252371194d11ee946e000c2904bb89", "subItemCode": "JLBYQ-SYZY-01-0005-SUBITEM-0002", "subItemName": "局放量测试值(峰值)", "conditionId": null, "conditionCode": null, "conditionName": null, "partsTypeId": "258f52ad194c11ee946e000c2904bb89", "partsTypeCode": "JLBYQ-SYZY-01-0005-POS-01", "partsTypeName": "测点个数", "testPartId": "1f022b23194c11ee946e000c2904bb89", "testPartCode": "JLBYQ-SYZY-01-0005-POS-01-030", "testPartName": "测点30", "fpartid": "1f0228f8194c11ee946e000c2904bb89", "fpartCode": "JLBYQ-SYZY-01-0005-POS-02-001", "fpartName": " 油(气)箱体左侧" }, { "testItemId": "27068c1f194a11ee946e000c2904bb89", "testItemCode": "JLBYQ-SYZY-01-0005", "testItemName": "交流变压器超声波(接触式)局放检测", "subItemId": "b4252371194d11ee946e000c2904bb89", "subItemCode": "JLBYQ-SYZY-01-0005-SUBITEM-0002", "subItemName": "局放量测试值(峰值)", "conditionId": null, "conditionCode": null, "conditionName": null, "partsTypeId": "258f52ad194c11ee946e000c2904bb89", "partsTypeCode": "JLBYQ-SYZY-01-0005-POS-01", "partsTypeName": "测点个数", "testPartId": "1f022b23194c11ee946
A4: 1 | B4: 查询公司规划报告信息接口 | C4: buaa_bpp_zxgz_09_cg01 | D4: compCode单位编码 ghVersion规划版本 reportName报告名录名称 ghYear规划滚动年份 departmentCode部门编码 isTc是否统筹部门 | E4: { "compCode": "21211115130229001", "ghVersion": "01", "reportName": "名录", "ghYear": "2023", "departmentCode": "21211115130229001", "isTc": "1" } | F4: compCode单位编码 ghVersion规划版本 reportName报告名录名称 ghYear规划滚动年份 departmentCode部门编码 isTc是否统筹部门 | G4: { "status": "000000", "message": "success", "data": { "total": "12"， "fileName": ""， "rows": [ { "index": 1, "compCode": "600001", "compName": "国家电网有限公司", "reportCode": "RPT20240101", "reportName": "2024年度财务报告", "reportMl": "年度报告", "reportClass": "", "departmentCode": "100", "departmentName": "", "professionalContact": "张三", "professionalContactMethod": "zhangsan@huaxia.com", "submitState": "已提交", "submitTime": "2024-01-01T08:00:00", "auditState": "审核中", "auditTime": "2024-01-02T09:00:00", "refuseReason": "", "auditContact": "李四", "auditContactMethod": "lisi@huaxia.com", "auditOpinion": "", "fileId": "FILE20240101XYZ", "ghVersion": "01", "ghYear": "2024", "auditStateCode": "1", "submitStateCode": "2" } ] } }
A5: 2 | B5: 查询规划评估报告信息接口 | C5: buaa_bpp_zxgz_09_cg02 | D5: compCode单位编码 ghVersion规划版本 ghYear规划滚动年份 | E5: { "compCode": "21211115130229001", "ghVersion": "01", "ghYear": "2023" } | F5: compCode单位编码 ghVersion规划版本 ghYear规划滚动年份 | G5: { "status": "000000", "message": "success", "data": { "total": "12"， "fileName": ""， "rows": [ { "index": 1, "compCode": "600001", "compName": "国家电网有限公司", "submitStateCode": " 1", "reportName": "2024年度财务报告", "professionalContact": "张三", "professionalContactMethod": "zhangsan@huaxia.com", "submitState": "已上报", "submitTime": "2024-01-01 08:00:00" "refuseReason": "", "fileId": "FILE20240101XYZ", "ghVersion": "01", "ghYear": "2023" } ] } }
A6: 3 | B6: 修改公司规划报告上报状态接口 | C6: buaa_bpp_zxgz_09_cg03 | D6: solidifyState操作类型（3 为上报4 为退回） compCode单位编码 ghVersion规划版本 reportCode报告编码（多个以逗号分割） ghYear规划滚动年份 | E6: { "solidifyState":"1", "ghVersion":"01", "ghYear":"2023", "compCode":"40101005110000001", "reportCode":""} | F6: solidifyState操作类型（3 为上报4 为退回） compCode单位编码 ghVersion规划版本 reportCode报告编码（多个以逗号分割） ghYear规划滚动年份 | G6: 操作类型为上报: { "status": "000000", "message": "报告上报成功" } 操作类型为退回: { "status": "000000", "message": "报告退回成功" }
A7: 4 | B7: 规划成果统计查询接口 | C7: buaa_bpp_zxgz_09_cg04 | D7: appId（调用方系统）、loginDeptCode（单位）、GHVersion（规划期间）、ghYear（规划年度）、fileType（文件类型）、deptRange（单位层级） | E7: { "appId":"00", "loginDeptCode":"40101005110000001", "GHVersion":"01", "deptCode": "40101005110000001", "fileType":"19", "ghYear":"2022", "deptRange":"0"} | F7: appId（调用方系统）、loginDeptCode（单位）、GHVersion（规划期间）、ghYear（规划年度）、fileType（文件类型）、deptRange（单位层级） | G7: {"data": [ { "dept_code": "40101005110000001", "count": 2 } ], "message": "调用接口正常", "fileCount": 2, "status": "pmp-100"}
A8: 5 | B8: 查询规划投资按地域分解信息接口 | C8: buaa_bpp_xmxt_01_xt01 | D8: deptCode 单位编码 planVersion 规划版本 year 规划滚动年份 indexCode 指标编码 isTemplateExport 是否模板导出 | E8: { "deptCode": "21211115130229001", "planVersion": "01", "year": 2023, "indexCode": "001", "isTemplateExport": "true" } | F8: deptCode 单位编码 planVersion 规划版本 year 规划滚动年份 indexCode 指标编码 isTemplateExport 是否模板导出 | G8: { "status": "000000", "message": "success", "data": { "total": "12", "fileName": "", "rows": [ { "rowNumber": 1, "deptCode": "40101005110000001", "deptName": "国家电网有限公司", "planDevotedType": "投资类型", "versionComplete": "100000", "completeFirst": "50000", "completeSecond": "60000", "completeThird": "70000", "completeFourth": "80000", "completeFifth": "90000", "children": [] } ] } }
A9: 6 | B9: 修改规划投资按地域分解信息接口 | C9: buaa_bpp_xmxt_01_xt02 | D9: immediateDept 单位编码 planVersion 规划版本 planYear 规划滚动年份 ghInvByRegionDecoModelList 区域投资分解模型列表 | E9: { "immediateDept": "100001", "planVersion": "01", "planYear": 2024, "ghInvByRegionDecoModelList": [ { "regionDecoInvId": 101, "indexCode": "IDX1001", "ghVersion": "01", "ghYear": 2024, "deptCode": "600001", "versionComplete": 500000.0, "complete2021": 100000.0, "complete2022": 200000.0, "complete2023": 300000.0, "complete2024": 400000.0, "complete2025": 500000.0, "decoDeptCode": "500001" } ] } | F9: immediateDept 单位编码 planVersion 规划版本 planYear 规划滚动年份 ghInvByRegionDecoModelList 区域投资分解模型列表 | G9: { "code": "000000", "message": "数据保存成功", "data": {} }
